<?xml version="1.0" encoding="UTF-8"?>
<testng-results skipped="0" failed="0" total="2" passed="2">
  <reporter-output>
  </reporter-output>
  <suite name="Default suite" duration-ms="24" started-at="2014-02-27T07:35:11Z" finished-at="2014-02-27T07:35:11Z">
    <groups>
    </groups>
    <test name="Default test" duration-ms="24" started-at="2014-02-27T07:35:11Z" finished-at="2014-02-27T07:35:11Z">
      <class name="com.caveofprogramming.spring.test.testprog.NewAppTest">
        <test-method status="PASS" signature="divisionWithException()[pri:0, instance:com.caveofprogramming.spring.test.testprog.NewAppTest@1d902242]" name="divisionWithException" duration-ms="9" started-at="2014-02-26T23:35:11Z" finished-at="2014-02-26T23:35:11Z">
          <exception class="java.lang.ArithmeticException">
            <message>
              <![CDATA[/ by zero]]>
            </message>
            <full-stacktrace>
              <![CDATA[java.lang.ArithmeticException: / by zero
	at com.caveofprogramming.spring.test.testprog.NewAppTest.divisionWithException(NewAppTest.java:16)
	at sun.reflect.NativeMethodAccessorImpl.invoke0(Native Method)
	at sun.reflect.NativeMethodAccessorImpl.invoke(NativeMethodAccessorImpl.java:57)
	at sun.reflect.DelegatingMethodAccessorImpl.invoke(DelegatingMethodAccessorImpl.java:43)
	at java.lang.reflect.Method.invoke(Method.java:606)
	at org.testng.internal.MethodInvocationHelper.invokeMethod(MethodInvocationHelper.java:84)
	at org.testng.internal.Invoker.invokeMethod(Invoker.java:714)
	at org.testng.internal.Invoker.invokeTestMethod(Invoker.java:901)
	at org.testng.internal.Invoker.invokeTestMethods(Invoker.java:1231)
	at org.testng.internal.TestMethodWorker.invokeTestMethods(TestMethodWorker.java:127)
	at org.testng.internal.TestMethodWorker.run(TestMethodWorker.java:111)
	at org.testng.TestRunner.privateRun(TestRunner.java:767)
	at org.testng.TestRunner.run(TestRunner.java:617)
	at org.testng.SuiteRunner.runTest(SuiteRunner.java:334)
	at org.testng.SuiteRunner.runSequentially(SuiteRunner.java:329)
	at org.testng.SuiteRunner.privateRun(SuiteRunner.java:291)
	at org.testng.SuiteRunner.run(SuiteRunner.java:240)
	at org.testng.SuiteRunnerWorker.runSuite(SuiteRunnerWorker.java:52)
	at org.testng.SuiteRunnerWorker.run(SuiteRunnerWorker.java:86)
	at org.testng.TestNG.runSuitesSequentially(TestNG.java:1224)
	at org.testng.TestNG.runSuitesLocally(TestNG.java:1149)
	at org.testng.TestNG.run(TestNG.java:1057)
	at org.testng.remote.RemoteTestNG.run(RemoteTestNG.java:111)
	at org.testng.remote.RemoteTestNG.initAndRun(RemoteTestNG.java:204)
	at org.testng.remote.RemoteTestNG.main(RemoteTestNG.java:175)
]]>
            </full-stacktrace>
          </exception> <!-- java.lang.ArithmeticException -->
          <reporter-output>
          </reporter-output>
        </test-method> <!-- divisionWithException -->
        <test-method status="PASS" signature="testGetString()[pri:0, instance:com.caveofprogramming.spring.test.testprog.NewAppTest@1d902242]" name="testGetString" duration-ms="3" started-at="2014-02-26T23:35:11Z" finished-at="2014-02-26T23:35:11Z">
          <reporter-output>
          </reporter-output>
        </test-method> <!-- testGetString -->
      </class> <!-- com.caveofprogramming.spring.test.testprog.NewAppTest -->
    </test> <!-- Default test -->
  </suite> <!-- Default suite -->
</testng-results>
